[2025-07-12T15:15:47.818+0000] {local_task_job_runner.py:120} INFO - ::group::Pre task execution logs
[2025-07-12T15:15:47.839+0000] {taskinstance.py:2076} INFO - Dependencies all met for dep_context=non-requeueable deps ti=<TaskInstance: dbt_workflow.dbt_run manual__2025-07-12T15:10:41.338733+00:00 [queued]>
[2025-07-12T15:15:47.845+0000] {taskinstance.py:2076} INFO - Dependencies all met for dep_context=requeueable deps ti=<TaskInstance: dbt_workflow.dbt_run manual__2025-07-12T15:10:41.338733+00:00 [queued]>
[2025-07-12T15:15:47.846+0000] {taskinstance.py:2306} INFO - Starting attempt 2 of 2
[2025-07-12T15:15:47.860+0000] {taskinstance.py:2330} INFO - Executing <Task(BashOperator): dbt_run> on 2025-07-12 15:10:41.338733+00:00
[2025-07-12T15:15:47.868+0000] {warnings.py:112} WARNING - /home/***/.local/lib/python3.12/site-packages/***/task/task_runner/standard_task_runner.py:61: DeprecationWarning: This process (pid=68) is multi-threaded, use of fork() may lead to deadlocks in the child.
  pid = os.fork()

[2025-07-12T15:15:47.870+0000] {standard_task_runner.py:63} INFO - Started process 70 to run task
[2025-07-12T15:15:47.870+0000] {standard_task_runner.py:90} INFO - Running: ['***', 'tasks', 'run', 'dbt_workflow', 'dbt_run', 'manual__2025-07-12T15:10:41.338733+00:00', '--job-id', '9', '--raw', '--subdir', 'DAGS_FOLDER/dbt_dag.py', '--cfg-path', '/tmp/tmpgtme6157']
[2025-07-12T15:15:47.873+0000] {standard_task_runner.py:91} INFO - Job 9: Subtask dbt_run
[2025-07-12T15:15:47.940+0000] {task_command.py:426} INFO - Running <TaskInstance: dbt_workflow.dbt_run manual__2025-07-12T15:10:41.338733+00:00 [running]> on host dd01d97ebd19
[2025-07-12T15:15:48.056+0000] {taskinstance.py:2648} INFO - Exporting env vars: AIRFLOW_CTX_DAG_OWNER='***' AIRFLOW_CTX_DAG_ID='dbt_workflow' AIRFLOW_CTX_TASK_ID='dbt_run' AIRFLOW_CTX_EXECUTION_DATE='2025-07-12T15:10:41.338733+00:00' AIRFLOW_CTX_TRY_NUMBER='2' AIRFLOW_CTX_DAG_RUN_ID='manual__2025-07-12T15:10:41.338733+00:00'
[2025-07-12T15:15:48.059+0000] {taskinstance.py:430} INFO - ::endgroup::
[2025-07-12T15:15:48.060+0000] {subprocess.py:63} INFO - Tmp dir root location: /tmp
[2025-07-12T15:15:48.061+0000] {subprocess.py:75} INFO - Running command: ['/usr/bin/bash', '-c', 'cd /opt/snowflake_data_project && dbt run']
[2025-07-12T15:15:48.074+0000] {subprocess.py:86} INFO - Output:
[2025-07-12T15:15:48.078+0000] {subprocess.py:93} INFO - /usr/bin/bash: line 1: dbt: command not found
[2025-07-12T15:15:48.079+0000] {subprocess.py:97} INFO - Command exited with return code 127
[2025-07-12T15:15:48.080+0000] {taskinstance.py:441} INFO - ::group::Post task execution logs
[2025-07-12T15:15:48.091+0000] {taskinstance.py:2905} ERROR - Task failed with exception
Traceback (most recent call last):
  File "/home/airflow/.local/lib/python3.12/site-packages/airflow/models/taskinstance.py", line 465, in _execute_task
    result = _execute_callable(context=context, **execute_callable_kwargs)
             ^^^^^^^^^^^^^^^^^^^^^^^^^^^^^^^^^^^^^^^^^^^^^^^^^^^^^^^^^^^^^
  File "/home/airflow/.local/lib/python3.12/site-packages/airflow/models/taskinstance.py", line 432, in _execute_callable
    return execute_callable(context=context, **execute_callable_kwargs)
           ^^^^^^^^^^^^^^^^^^^^^^^^^^^^^^^^^^^^^^^^^^^^^^^^^^^^^^^^^^^^
  File "/home/airflow/.local/lib/python3.12/site-packages/airflow/models/baseoperator.py", line 401, in wrapper
    return func(self, *args, **kwargs)
           ^^^^^^^^^^^^^^^^^^^^^^^^^^^
  File "/home/airflow/.local/lib/python3.12/site-packages/airflow/operators/bash.py", line 243, in execute
    raise AirflowException(
airflow.exceptions.AirflowException: Bash command failed. The command returned a non-zero exit code 127.
[2025-07-12T15:15:48.097+0000] {taskinstance.py:1206} INFO - Marking task as FAILED. dag_id=dbt_workflow, task_id=dbt_run, run_id=manual__2025-07-12T15:10:41.338733+00:00, execution_date=20250712T151041, start_date=20250712T151547, end_date=20250712T151548
[2025-07-12T15:15:48.111+0000] {standard_task_runner.py:110} ERROR - Failed to execute job 9 for task dbt_run (Bash command failed. The command returned a non-zero exit code 127.; 70)
[2025-07-12T15:15:48.126+0000] {local_task_job_runner.py:240} INFO - Task exited with return code 1
[2025-07-12T15:15:48.152+0000] {taskinstance.py:3503} INFO - 0 downstream tasks scheduled from follow-on schedule check
[2025-07-12T15:15:48.157+0000] {local_task_job_runner.py:222} INFO - ::endgroup::
